<mujoco>
	<compiler angle="radian" coordinate="local" meshdir="../stls" texturedir="../textures" />
	<option timestep="0.002">
		<flag warmstart="enable" />
	</option>

	<include file="shared.xml" />

    <asset>
        <include file="shared_asset.xml" />
    </asset>
	
	<worldbody>
		<geom name="floor0" pos="0.8 0.75 0" size="0.85 0.7 1" type="plane" condim="3" material="floor_mat" />
		<body name="floor0" pos="0.8 0.75 0">
			<site name="target0" pos="0 0 0.5" size="0.02 0.02 0.02" rgba="1 0 0 1" type="sphere" />
		</body>

		<include file="robot.xml" />
		
		<body pos="1.3 0.75 0.2" name="table0">
			<geom size="0.25 0.35 0.2" type="box" mass="2000" material="table_mat" />
		</body>


		<body name="object0" pos="1.46177789 0.74909766 0.60">
			<joint name="object0:joint" type="slide" axis="0 0 1" damping="0.5" limited="true" range="-0.138 10." frictionloss="1.0" />
			<geom size="0.005 0.060" type="cylinder" condim="3" name="object0" material="block_mat" mass="2" />

			<site name="object0" pos="0 0 0" size="0.02 0.02 0.02" rgba="1 0 0 1" type="sphere" />
		</body>

		<light directional="true" ambient="0.2 0.2 0.2" diffuse="0.8 0.8 0.8" specular="0.3 0.3 0.3" castshadow="false" pos="0 0 4" dir="0 0 -1" name="light0" />
	</worldbody>

    <sensor>
        <jointpos name="object0:h" joint="object0:joint" />
        <force name="object0:f" site="object0" />
	</sensor>





</mujoco>