<mujoco>
	<compiler angle="radian" coordinate="local" meshdir="../stls" texturedir="../textures" />
	<option timestep="0.002">
		<flag warmstart="enable" />
	</option>

	<include file="shared.xml" />

    <asset>
        <include file="shared_asset.xml" />
    </asset>
	
	<worldbody>
		<geom name="floor0" pos="0.8 0.75 0" size="0.85 0.7 1" type="plane" condim="3" material="floor_mat" />
		<body name="floor0" pos="0.8 0.75 0">
			<site name="target0" pos="0 0 0.5" size="0.02 0.02 0.02" rgba="1 0 0 1" type="sphere" />
		</body>

		<include file="robot.xml" />

		<body pos="1.3006656738830575 0.5733490285811009 0.15" name="table0">
			<geom size="0.25 0.1725 0.2" type="box" mass="2000" material="table_mat" />
		</body>

		<body pos="1.3006656738830575 0.9283490285811009 0.15" name="table1">
			<geom size="0.25 0.1725 0.2" type="box" mass="2000" material="table_mat" />
		</body>

		<body pos="1.2531656738830574 0.7508490285811009 0.15" name="table2">
			<geom size="0.2025 0.005 0.2" type="box" mass="2000" material="table_mat" />
		</body>

		<body pos="1.5081656738830576 0.7508490285811009 0.15" name="table3">
			<geom size="0.0425 0.005 0.2" type="box" mass="2000" material="table_mat" />
		</body>


		<body name="object0" pos="1.4624435638830575 0.7499466885811009 0.6">
			<joint name="object0:joint" type="slide" axis="0 0 1" damping="0.5" limited="true" range="-0.138 10." frictionloss="1.0" />
			<geom pos="0 0 -0.06" size="0.001 0.12" type="cylinder" condim="3" name="object0" material="block_mat" mass="2" />


			<site name="object0" pos="0 0 0" size="0.02 0.02 0.02" rgba="1 0 0 1" type="sphere" />
		<geom name="object00" pos="0 0 -0.06" size="0.012892962473213226 0.006" type="cylinder" condim="3" material="block_mat" mass="0" /><geom name="object01" pos="0 0 -0.048" size="0.015314369978570582 0.006" type="cylinder" condim="3" material="block_mat" mass="0" /><geom name="object02" pos="0 0 -0.036" size="0.017735777483927937 0.006" type="cylinder" condim="3" material="block_mat" mass="0" /><geom name="object03" pos="0 0 -0.023999999999999994" size="0.02015718498928529 0.006" type="cylinder" condim="3" material="block_mat" mass="0" /><geom name="object04" pos="0 0 -0.011999999999999997" size="0.022578592494642648 0.006" type="cylinder" condim="3" material="block_mat" mass="0" /><geom name="object05" pos="0 0 0.0" size="0.025 0.006" type="cylinder" condim="3" material="block_mat" mass="0" /><geom name="object06" pos="0 0 0.01200000000000001" size="0.027421407505357355 0.006" type="cylinder" condim="3" material="block_mat" mass="0" /><geom name="object07" pos="0 0 0.024000000000000007" size="0.029842815010714712 0.006" type="cylinder" condim="3" material="block_mat" mass="0" /><geom name="object08" pos="0 0 0.036000000000000004" size="0.03226422251607207 0.006" type="cylinder" condim="3" material="block_mat" mass="0" /><geom name="object09" pos="0 0 0.048" size="0.03468563002142942 0.006" type="cylinder" condim="3" material="block_mat" mass="0" /></body>

		<light directional="true" ambient="0.2 0.2 0.2" diffuse="0.8 0.8 0.8" specular="0.3 0.3 0.3" castshadow="false" pos="0 0 4" dir="0 0 -1" name="light0" />
	</worldbody>

    <sensor>
        <jointpos name="object0:h" joint="object0:joint" />
        <force name="object0:f" site="object0" />
	</sensor>





</mujoco>